Workbook

Sheet Tổng quát
A1: TỔNG QUÁT DANH SÁCH CÔNG TY / COMPANY LIST OVERVIEW
A2: Nguồn: Sheet1 (cột F "Loại", cột H "Trạng thái lấy mẫu captcha" = "Xong") / Source: Sheet1
A4: STT No. | B4: Loại Type | C4: Số công ty Companies | D4: Đã lấy mẫu captcha (Xong) Captcha sampled | E4: Chưa làm Not yet
A5: 1 | B5: Không có captcha | C5: 90 | D5: =COUNTIFS('Chi tiết'!$F$2:$F$1000,B5,'Chi tiết'!$I$2:$I$1000,"Xong") -> 0 | E5: =C5-D5 -> 90
A6: 2 | B6: có captcha | C6: =COUNTIF('Chi tiết'!$F$2:$F$1000,B6) -> 24 | D6: =COUNTIFS('Chi tiết'!$F$2:$F$1000,B6,'Chi tiết'!$I$2:$I$1000,"Xong") -> 23 | E6: =C6-D6 -> 1
A7: 3 | B7: captcha dạng tích | C7: =COUNTIF('Chi tiết'!$F$2:$F$1000,B7) -> 11 | D7: =COUNTIFS('Chi tiết'!$F$2:$F$1000,B7,'Chi tiết'!$I$2:$I$1000,"Xong") -> 0 | E7: =C7-D7 -> 11
A8: 4 | B8: domain không phân giải | C8: 5 | D8: =COUNTIFS('Chi tiết'!$F$2:$F$1000,B8,'Chi tiết'!$I$2:$I$1000,"Xong") -> 0 | E8: =C8-D8 -> 5
A9: 5 | B9: đăng nhập mới xem hóa đơn | C9: =COUNTIF('Chi tiết'!$F$2:$F$1000,B9) -> 1 | D9: =COUNTIFS('Chi tiết'!$F$2:$F$1000,B9,'Chi tiết'!$I$2:$I$1000,"Xong") -> 0 | E9: =C9-D9 -> 1
A10: 6 | B10: lỗi máy chủ | C10: =COUNTIF('Chi tiết'!$F$2:$F$1000,B10) -> 2 | D10: =COUNTIFS('Chi tiết'!$F$2:$F$1000,B10,'Chi tiết'!$I$2:$I$1000,"Xong") -> 0 | E10: =C10-D10 -> 2
A11: 7 | B11: dạng hình ảnh | C11: =COUNTIF('Chi tiết'!$F$2:$F$1000,B11) -> 1 | D11: =COUNTIFS('Chi tiết'!$F$2:$F$1000,B11,'Chi tiết'!$I$2:$I$1000,"Xong") -> 0 | E11: =C11-D11 -> 1
A12: 8 | B12: site đã đổi chủ (redirect sang sanmuasam.com) | C12: =COUNTIF('Chi tiết'!$F$2:$F$1000,B12) -> 1 | D12: =COUNTIFS('Chi tiết'!$F$2:$F$1000,B12,'Chi tiết'!$I$2:$I$1000,"Xong") -> 0 | E12: =C12-D12 -> 1
A13: 9 | B13: đọc xml | C13: =COUNTIF('Chi tiết'!$F$2:$F$1000,B13) -> 1 | D13: =COUNTIFS('Chi tiết'!$F$2:$F$1000,B13,'Chi tiết'!$I$2:$I$1000,"Xong") -> 0 | E13: =C13-D13 -> 1
A14: 10 | B14: site đã đổi chủ (redirect sang trang cờ bạc) | C14: =COUNTIF('Chi tiết'!$F$2:$F$1000,B14) -> 1 | D14: =COUNTIFS('Chi tiết'!$F$2:$F$1000,B14,'Chi tiết'!$I$2:$I$1000,"Xong") -> 0 | E14: =C14-D14 -> 1
A15: 11 | B15: site lỗi 503 | C15: =COUNTIF('Chi tiết'!$F$2:$F$1000,B15) -> 1 | D15: =COUNTIFS('Chi tiết'!$F$2:$F$1000,B15,'Chi tiết'!$I$2:$I$1000,"Xong") -> 0 | E15: =C15-D15 -> 1
B16: TỔNG / TOTAL | C16: =SUM(C5:C15) -> 138 | D16: =SUM(D5:D15) -> 23 | E16: =SUM(E5:E15) -> 115
B18: NHÓM CÓ CAPTCHA / CAPTCHA GROUP TRAINING AI
B19: Loại / Type | C19: Số công ty / Companies | D19: Đã làm / Done | E19: Tỷ lệ / %
B20: có captcha | C20: =COUNTIF('Chi tiết'!$F$2:$F$1000,B20) -> 24 | D20: 11 | E20: =IF(C20=0,0,D20/C20) -> 0.45833333
B21: captcha dạng tích | C21: =COUNTIF('Chi tiết'!$F$2:$F$1000,B21) -> 11 | D21: =COUNTIFS('Chi tiết'!$F$2:$F$1000,B21,'Chi tiết'!$I$2:$I$1000,"Xong") -> 0 | E21: =IF(C21=0,0,D21/C21) -> 0
B22: dạng hình ảnh | C22: =COUNTIF('Chi tiết'!$F$2:$F$1000,B22) -> 1 | D22: =COUNTIFS('Chi tiết'!$F$2:$F$1000,B22,'Chi tiết'!$I$2:$I$1000,"Xong") -> 0 | E22: =IF(C22=0,0,D22/C22) -> 0
B23: Tổng nhóm captcha / Group total | C23: =SUM(C20:C22) -> 36 | D23: =SUM(D20:D22) -> 11 | E23: =IF(C23=0,0,D23/C23) -> 0.30555556
B25: Ghi chú / Notes:
B26: "Không có captcha" và "không có captcha" (khác hoa/thường) được gộp làm một. / Case variants merged.
B27: Nhóm captcha giả định gồm: có captcha, captcha dạng tích, dạng hình ảnh. / Assumed captcha group.
B28: Đối chiếu tổng số dòng Sheet1 (cột B): | E28: =COUNTA('Chi tiết'!$B$2:$B$1000) -> 138
B30: KHẢO SÁT FORM TRA CỨU HÓA ĐƠN / LOOKUP FORM SURVEY
B31: Nguồn: sheet 'Chi tiết' cột M–AB (khảo sát 14/10/2026, ✓ = tham số của form tra cứu mặc định). Số liệu là công thức, tự cập nhật.
B33: 1. Trạng thái kiểm tra form / Check status
B34: Trạng thái / Status | C34: Số công ty / Companies | D34: Tỷ lệ / %
A35: 1 | B35: OK | C35: =COUNTIF('Chi tiết'!$N$2:$N$1000,B35) -> 106 | D35: =IF($C$40=0,0,C35/$C$40) -> 0.9380531
A36: 2 | B36: Cần đăng nhập | C36: =COUNTIF('Chi tiết'!$N$2:$N$1000,B36) -> 4 | D36: =IF($C$40=0,0,C36/$C$40) -> 0.03539823
A37: 3 | B37: Site chết | C37: =COUNTIF('Chi tiết'!$N$2:$N$1000,B37) -> 0 | D37: =IF($C$40=0,0,C37/$C$40) -> 0
A38: 4 | B38: Site lỗi | C38: =COUNTIF('Chi tiết'!$N$2:$N$1000,B38) -> 2 | D38: =IF($C$40=0,0,C38/$C$40) -> 0.017699115
A39: 5 | B39: Không xác định | C39: =COUNTIF('Chi tiết'!$N$2:$N$1000,B39) -> 1 | D39: =IF($C$40=0,0,C39/$C$40) -> 0.0088495575
B40: Tổng đã kiểm tra / Checked | C40: =SUM(C35:C39) -> 113 | D40: =IF(C40=0,0,1) -> 1
B42: 2. Tham số form yêu cầu (trên các site OK) / Required inputs
B43: Tham số / Input | C43: Số công ty / Companies | D43: Tỷ lệ trên site OK / % of OK
A44: 1 | B44: Mã tra cứu | C44: =COUNTIFS('Chi tiết'!$N$2:$N$1000,"OK",'Chi tiết'!$O$2:$O$1000,"✓") -> 104 | D44: =IF($C$35=0,0,C44/$C$35) -> 0.98113208
A45: 2 | B45: MST người bán | C45: =COUNTIFS('Chi tiết'!$N$2:$N$1000,"OK",'Chi tiết'!$P$2:$P$1000,"✓") -> 25 | D45: =IF($C$35=0,0,C45/$C$35) -> 0.23584906
A46: 3 | B46: MST người mua | C46: =COUNTIFS('Chi tiết'!$N$2:$N$1000,"OK",'Chi tiết'!$Q$2:$Q$1000,"✓") -> 1 | D46: =IF($C$35=0,0,C46/$C$35) -> 0.0094339623
...

Sheet Chi tiết
A1: STT | B1: Tên công ty | C1: Mã số thuế | D1: Địa chỉ | E1: Web | F1: Loại | G1: Link tra cứu nếu có | H1: Kiểu tra cứu (tổ hợp tham số) | I1: Trạng thái lấy mẫu captcha | K1: Train cho AI(%) | L1: Mã kích thước | N1: Kiểm tra form tra cứu | O1: Mã tra cứu | P1: MST người bán | Q1: MST người mua | R1: Mẫu số / Ký hiệu | S1: Số HĐ | T1: Ngày lập | U1: Tổng tiền | V1: Mã CQT | W1: Upload XML | X1: Captcha ảnh | Y1: Captcha dạng tích | Z1: Captcha khác (slider/hình) | AA1: Đăng nhập | AB1: Email/SĐT/OTP | AC1: Số tham số nhập | AD1: Captcha chi tiết | AE1: Cách tra khác | AF1: Ghi chú kiểm tra | AG1: URL form đã kiểm tra | AJ1: Training captcha (WBS2) | AK1: PDF qua XML – Status (WBS2) | AL1: PDF qua XML – Kế hoạch đến | AM1: PDF qua XML – Ghi chú (WBS2) | AN1: PDF qua mail – Status (WBS2) | AO1: PDF qua mail – Kế hoạch đến | AP1: PDF qua mail – Ghi chú (WBS2)
A2: 1 | B2: Công ty TNHH Công nghệ Vĩnh Hy | C2: 0314743623 | D2: 82 Đường 76, Phường 10, Quận 6, Tp Hồ Chí Minh | E2: http://ehoadondientu.com | F2: Không có captcha | G2: https://ehoadondientu.com/Tra-cuu | H2: =IF(N2<>"OK","",IF(IF(O2="✓","Mã tra cứu|","")&IF(P2="✓","MST người bán|","")&IF(Q2="✓","MST người mua|","")&IF(R2="✓","Mẫu số / Ký hiệu|","")&IF(S2="✓","Số HĐ|","")&IF(T2="✓","Ngày lập|","")&IF(U2="✓","Tổng tiền|","")&IF(V2="✓","Mã CQT|","")&IF(W2="✓","Upload XML|","")&IF(X2="✓","Captcha ảnh|","")&IF(Y2="✓","Captcha dạng tích|","")&IF(Z2="✓","Captcha khác (slider/hình)|","")&IF(AA2="✓","Đăng nhập|","")&IF(AB2="✓","Email/SĐT/OTP|","")="","(không có tham số)",SUBSTITUTE(LEFT(IF(O2="✓","Mã tra cứu|","")&IF(P2="✓","MST người bán|","")&IF(Q2="✓","MST người mua|","")&IF(R2="✓","Mẫu số / Ký hiệu|","")&IF(S2="✓","Số HĐ|","")&IF(T2="✓","Ngày lập|","")&IF(U2="✓","Tổng tiền|","")&IF(V2="✓","Mã CQT|","")&IF(W2="✓","Upload XML|","")&IF(X2="✓","Captcha ảnh|","")&IF(Y2="✓","Captcha dạng tích|","")&IF(Z2="✓","Captcha khác (slider/hình)|","")&IF(AA2="✓","Đăng nhập|","")&IF(AB2="✓","Email/SĐT/OTP|",""),LEN(IF(O2="✓","Mã tra cứu|","")&IF(P2="✓","MST người bán|","")&IF(Q2="✓","MST người mua|","")&IF(R2="✓","Mẫu số / Ký hiệu|","")&IF(S2="✓","Số HĐ|","")&IF(T2="✓","Ngày lập|","")&IF(U2="✓","Tổng tiền|","")&IF(V2="✓","Mã CQT|","")&IF(W2="✓","Upload XML|","")&IF(X2="✓","Captcha ảnh|","")&IF(Y2="✓","Captcha dạng tích|","")&IF(Z2="✓","Captcha khác (slider/hình)|","")&IF(AA2="✓","Đăng nhập|","")&IF(AB2="✓","Email/SĐT/OTP|",""))-1),"|"," + "))) -> Mã tra cứu | N2: OK | O2: ✓ | AC2: 1 | AD2: không có | AE2: Dropdown 'Mã số thuế': vẫn 1 ô 'Mã hóa đơn hoặc mst'; dropdown 'Chứng từ khấu trừ thuế': MST + ký hiệu + số + họ tên + thu nhập (chứng từ TNCN); link 'Tra cứu hóa đơn bằng tài khoản khách hàng' (đăng nhập) | AF2: 1 ô nhập chung 'Mã hóa đơn hoặc mst' + dropdown loại tra cứu; không captcha | AG2: https://ehoadondientu.com/Tra-cuu | AJ2: =IFERROR(IF(INDEX('WBS2'!$I$2:$I$25,MATCH($C2,'WBS2'!$F$2:$F$25,0))="","",INDEX('WBS2'!$I$2:$I$25,MATCH($C2,'WBS2'!$F$2:$F$25,0))),"") | AK2: =IFERROR(IF(INDEX('WBS2'!$I$27:$I$162,MATCH($C2,'WBS2'!$F$27:$F$162,0))="","",INDEX('WBS2'!$I$27:$I$162,MATCH($C2,'WBS2'!$F$27:$F$162,0))),"") -> Hoàn thành | AL2: =IFERROR(IF(OR($AK2="Chưa hoàn thành",$AK2="Sẵn sàng"),INDEX('WBS2'!$H$27:$H$162,MATCH($C2,'WBS2'!$F$27:$F$162,0)),""),"") | AM2: =IFERROR(IF(INDEX('WBS2'!$J$27:$J$162,MATCH($C2,'WBS2'!$F$27:$F$162,0))="","",INDEX('WBS2'!$J$27:$J$162,MATCH($C2,'WBS2'!$F$27:$F$162,0))),"") | AN2: =IFERROR(IF(INDEX('WBS2'!$I$163:$I$298,MATCH($C2,'WBS2'!$F$163:$F$298,0))="","",INDEX('WBS2'!$I$163:$I$298,MATCH($C2,'WBS2'!$F$163:$F$298,0))),"") -> Hoàn thành | AO2: =IFERROR(IF(OR($AN2="Chưa hoàn thành",$AN2="Sẵn sàng"),INDEX('WBS2'!$H$163:$H$298,MATCH($C2,'WBS2'!$F$163:$F$298,0)),""),"") | AP2: =IFERROR(IF(INDEX('WBS2'!$J$163:$J$298,MATCH($C2,'WBS2'!$F$163:$F$298,0))="","",INDEX('WBS2'!$J$163:$J$298,MATCH($C2,'WBS2'!$F$163:$F$298,0))),"")
A3: 2 | B3: Công ty TNHH Hệ thống thông tin FPT | C3: 0104128565 | D3: Tầng 22, tòa nhà Keangnam Landmark, E6 Phạm Hùng, quận Nam Từ Liêm, Tp Hà Nội | E3: https://einvoice.fpt.com.vn | F3: Không có captcha | G3: https://tracuuhoadon.fpt.com.vn/ | H3: =IF(N3<>"OK","",IF(IF(O3="✓","Mã tra cứu|","")&IF(P3="✓","MST người bán|","")&IF(Q3="✓","MST người mua|","")&IF(R3="✓","Mẫu số / Ký hiệu|","")&IF(S3="✓","Số HĐ|","")&IF(T3="✓","Ngày lập|","")&IF(U3="✓","Tổng tiền|","")&IF(V3="✓","Mã CQT|","")&IF(W3="✓","Upload XML|","")&IF(X3="✓","Captcha ảnh|","")&IF(Y3="✓","Captcha dạng tích|","")&IF(Z3="✓","Captcha khác (slider/hình)|","")&IF(AA3="✓","Đăng nhập|","")&IF(AB3="✓","Email/SĐT/OTP|","")="","(không có tham số)",SUBSTITUTE(LEFT(IF(O3="✓","Mã tra cứu|","")&IF(P3="✓","MST người bán|","")&IF(Q3="✓","MST người mua|","")&IF(R3="✓","Mẫu số / Ký hiệu|","")&IF(S3="✓","Số HĐ|","")&IF(T3="✓","Ngày lập|","")&IF(U3="✓","Tổng tiền|","")&IF(V3="✓","Mã CQT|","")&IF(W3="✓","Upload XML|","")&IF(X3="✓","Captcha ảnh|","")&IF(Y3="✓","Captcha dạng tích|","")&IF(Z3="✓","Captcha khác (slider/hình)|","")&IF(AA3="✓","Đăng nhập|","")&IF(AB3="✓","Email/SĐT/OTP|",""),LEN(IF(O3="✓","Mã tra cứu|","")&IF(P3="✓","MST người bán|","")&IF(Q3="✓","MST người mua|","")&IF(R3="✓","Mẫu số / Ký hiệu|","")&IF(S3="✓","Số HĐ|","")&IF(T3="✓","Ngày lập|","")&IF(U3="✓","Tổng tiền|","")&IF(V3="✓","Mã CQT|","")&IF(W3="✓","Upload XML|","")&IF(X3="✓","Captcha ảnh|","")&IF(Y3="✓","Captcha dạng tích|","")&IF(Z3="✓","Captcha khác (slider/hình)|","")&IF(AA3="✓","Đăng nhập|","")&IF(AB3="✓","Email/SĐT/OTP|",""))-1),"|"," + "))) -> Mã tra cứu + MST người bán | N3: OK | O3: ✓ | P3: ✓ | AC3: 2 | AD3: reCAPTCHA v3 ẩn (api.js?render=<key>, chỉ có badge, không có ô tích) | AE3: Tab 'Tra cứu nhiều HĐ': đăng nhập MST + tài khoản + mật khẩu; các tab khác: Chứng từ khấu trừ thuế, Đề nghị xuất HĐ, Công cụ, Biên bản, Bảng kê | AF3: SPA (Webix); MST bên bán + mã tra cứu | AG3: https://tracuuhoadon.fpt.com.vn/ | AJ3: =IFERROR(IF(INDEX('WBS2'!$I$2:$I$25,MATCH($C3,'WBS2'!$F$2:$F$25,0))="","",INDEX('WBS2'!$I$2:$I$25,MATCH($C3,'WBS2'!$F$2:$F$25,0))),"") | AK3: =IFERROR(IF(INDEX('WBS2'!$I$27:$I$162,MATCH($C3,'WBS2'!$F$27:$F$162,0))="","",INDEX('WBS2'!$I$27:$I$162,MATCH($C3,'WBS2'!$F$27:$F$162,0))),"") -> Chưa hoàn thành | AL3: =IFERROR(IF(OR($AK3="Chưa hoàn thành",$AK3="Sẵn sàng"),INDEX('WBS2'!$H$27:$H$162,MATCH($C3,'WBS2'!$F$27:$F$162,0)),""),"") -> 46446 | AM3: =IFERROR(IF(INDEX('WBS2'!$J$27:$J$162,MATCH($C3,'WBS2'!$F$27:$F$162,0))="","",INDEX('WBS2'!$J$27:$J$162,MATCH($C3,'WBS2'!$F$27:$F$162,0))),"") -> bị chặn bởi reCAPTCHA, lấy qua mail. dính reCAPTCHA v3 | AN3: =IFERROR(IF(INDEX('WBS2'!$I$163:$I$298,MATCH($C3,'WBS2'!$F$163:$F$298,0))="","",INDEX('WBS2'!$I$163:$I$298,MATCH($C3,'WBS2'!$F$163:$F$298,0))),"") -> Hoàn thành | AO3: =IFERROR(IF(OR($AN3="Chưa hoàn thành",$AN3="Sẵn sàng"),INDEX('WBS2'!$H$163:$H$298,MATCH($C3,'WBS2'!$F$163:$F$298,0)),""),"") | AP3: =IFERROR(IF(INDEX('WBS2'!$J$163:$J$298,MATCH($C3,'WBS2'!$F$163:$F$298,0))="","",INDEX('WBS2'!$J$163:$J$298,MATCH($C3,'WBS2'!$F$163:$F$298,0))),"")
A4: 3 | B4: Công ty Cổ phần Công nghệ tin học EFY Việt Nam | C4: 0102519041 | D4: Tầng 9, tòa nhà Sannam, số 78 phố Duy Tân, phường Dịch Vọng Hậu, quận Cầu Giấy, Tp Hà Nội | E4: https://ihoadon.vn | F4: captcha dạng tích | G4: https://ihoadon.vn/kiem-tra/?lang=vn | H4: =IF(N4<>"OK","",IF(IF(O4="✓","Mã tra cứu|","")&IF(P4="✓","MST người bán|","")&IF(Q4="✓","MST người mua|","")&IF(R4="✓","Mẫu số / Ký hiệu|","")&IF(S4="✓","Số HĐ|","")&IF(T4="✓","Ngày lập|","")&IF(U4="✓","Tổng tiền|","")&IF(V4="✓","Mã CQT|","")&IF(W4="✓","Upload XML|","")&IF(X4="✓","Captcha ảnh|","")&IF(Y4="✓","Captcha dạng tích|","")&IF(Z4="✓","Captcha khác (slider/hình)|","")&IF(AA4="✓","Đăng nhập|","")&IF(AB4="✓","Email/SĐT/OTP|","")="","(không có tham số)",SUBSTITUTE(LEFT(IF(O4="✓","Mã tra cứu|","")&IF(P4="✓","MST người bán|","")&IF(Q4="✓","MST người mua|","")&IF(R4="✓","Mẫu số / Ký hiệu|","")&IF(S4="✓","Số HĐ|","")&IF(T4="✓","Ngày lập|","")&IF(U4="✓","Tổng tiền|","")&IF(V4="✓","Mã CQT|","")&IF(W4="✓","Upload XML|","")&IF(X4="✓","Captcha ảnh|","")&IF(Y4="✓","Captcha dạng tích|","")&IF(Z4="✓","Captcha khác (slider/hình)|","")&IF(AA4="✓","Đăng nhập|","")&IF(AB4="✓","Email/SĐT/OTP|",""),LEN(IF(O4="✓","Mã tra cứu|","")&IF(P4="✓","MST người bán|","")&IF(Q4="✓","MST người mua|","")&IF(R4="✓","Mẫu số / Ký hiệu|","")&IF(S4="✓","Số HĐ|","")&IF(T4="✓","Ngày lập|","")&IF(U4="✓","Tổng tiền|","")&IF(V4="✓","Mã CQT|","")&IF(W4="✓","Upload XML|","")&IF(X4="✓","Captcha ảnh|","")&IF(Y4="✓","Captcha dạng tích|","")&IF(Z4="✓","Captcha khác (slider/hình)|","")&IF(AA4="✓","Đăng nhập|","")&IF(AB4="✓","Email/SĐT/OTP|",""))-1),"|"," + "))) -> Mã tra cứu + Số HĐ + Captcha dạng tích | N4: OK | O4: ✓ | S4: ✓ | Y4: ✓ | AC4: 3 | AD4: reCAPTCHA v2 checkbox (Enterprise) | AE4: Radio 'Từ file': upload file HĐ | AF4: AngularJS; ô 2 nhận 'mã tra cứu hoặc chuỗi xác thực hóa đơn' | AG4: https://ihoadon.vn/kiem-tra/?lang=vn | AJ4: =IFERROR(IF(INDEX('WBS2'!$I$2:$I$25,MATCH($C4,'WBS2'!$F$2:$F$25,0))="","",INDEX('WBS2'!$I$2:$I$25,MATCH($C4,'WBS2'!$F$2:$F$25,0))),"") | AK4: =IFERROR(IF(INDEX('WBS2'!$I$27:$I$162,MATCH($C4,'WBS2'!$F$27:$F$162,0))="","",INDEX('WBS2'!$I$27:$I$162,MATCH($C4,'WBS2'!$F$27:$F$162,0))),"") -> Chưa hoàn thành | AL4: =IFERROR(IF(OR($AK4="Chưa hoàn thành",$AK4="Sẵn sàng"),INDEX('WBS2'!$H$27:$H$162,MATCH($C4,'WBS2'!$F$27:$F$162,0)),""),"") -> 46446 | AM4: =IFERROR(IF(INDEX('WBS2'!$J$27:$J$162,MATCH($C4,'WBS2'!$F$27:$F$162,0))="","",INDEX('WBS2'!$J$27:$J$162,MATCH($C4,'WBS2'!$F$27:$F$162,0))),"") -> bị chặn bởi reCAPTCHA, lấy qua mail. dính reCAPTCHA v3 | AN4: =IFERROR(IF(INDEX('WBS2'!$I$163:$I$298,MATCH($C4,'WBS2'!$F$163:$F$298,0))="","",INDEX('WBS2'!$I$163:$I$298,MATCH($C4,'WBS2'!$F$163:$F$298,0))),"") -> Hoàn thành | AO4: =IFERROR(IF(OR($AN4="Chưa hoàn thành",$AN4="Sẵn sàng"),INDEX('WBS2'!$H$163:$H$298,MATCH($C4,'WBS2'!$F$163:$F$298,0)),""),"") | AP4: =IFERROR(IF(INDEX('WBS2'!$J$163:$J$298,MATCH($C4,'WBS2'!$F$163:$F$298,0))="","",INDEX('WBS2'!$J$163:$J$298,MATCH($C4,'WBS2'!$F$163:$F$298,0))),"")
A5: 4 | B5: Công ty Cổ phần Đầu tư công nghệ và thương mại Softdreams | C5: 0105987432 | D5: Số 7, ngách 97/1, ngõ 97 Chính Kinh, phường Nhân Chính, quận Thanh Xuân, Tp Hà Nội | E5: https://easyinvoice.vn | F5: có captcha | G5: https://tracuu.easyinvoice.vn/Captcha/Show | H5: =IF(N5<>"OK","",IF(IF(O5="✓","Mã tra cứu|","")&IF(P5="✓","MST người bán|","")&IF(Q5="✓","MST người mua|","")&IF(R5="✓","Mẫu số / Ký hiệu|","")&IF(S5="✓","Số HĐ|","")&IF(T5="✓","Ngày lập|","")&IF(U5="✓","Tổng tiền|","")&IF(V5="✓","Mã CQT|","")&IF(W5="✓","Upload XML|","")&IF(X5="✓","Captcha ảnh|","")&IF(Y5="✓","Captcha dạng tích|","")&IF(Z5="✓","Captcha khác (slider/hình)|","")&IF(AA5="✓","Đăng nhập|","")&IF(AB5="✓","Email/SĐT/OTP|","")="","(không có tham số)",SUBSTITUTE(LEFT(IF(O5="✓","Mã tra cứu|","")&IF(P5="✓","MST người bán|","")&IF(Q5="✓","MST người mua|","")&IF(R5="✓","Mẫu số / Ký hiệu|","")&IF(S5="✓","Số HĐ|","")&IF(T5="✓","Ngày lập|","")&IF(U5="✓","Tổng tiền|","")&IF(V5="✓","Mã CQT|","")&IF(W5="✓","Upload XML|","")&IF(X5="✓","Captcha ảnh|","")&IF(Y5="✓","Captcha dạng tích|","")&IF(Z5="✓","Captcha khác (slider/hình)|","")&IF(AA5="✓","Đăng nhập|","")&IF(AB5="✓","Email/SĐT/OTP|",""),LEN(IF(O5="✓","Mã tra cứu|","")&IF(P5="✓","MST người bán|","")&IF(Q5="✓","MST người mua|","")&IF(R5="✓","Mẫu số / Ký hiệu|","")&IF(S5="✓","Số HĐ|","")&IF(T5="✓","Ngày lập|","")&IF(U5="✓","Tổng tiền|","")&IF(V5="✓","Mã CQT|","")&IF(W5="✓","Upload XML|","")&IF(X5="✓","Captcha ảnh|","")&IF(Y5="✓","Captcha dạng tích|","")&IF(Z5="✓","Captcha khác (slider/hình)|","")&IF(AA5="✓","Đăng nhập|","")&IF(AB5="✓","Email/SĐT/OTP|",""))-1),"|"," + "))) -> Mã tra cứu + MST người bán + Captcha ảnh | I5: Xong | K5: 0.949 | L5: g_150x34 | M5: https://tracuu.easyinvoice.vn/Captcha/Show | N5: OK | O5: ✓ | P5: ✓ | X5: ✓ | AC5: 3 | AD5: ảnh 150x34 (/Captcha/Show) | AE5: Menu khác: tra cứu phiếu xuất kho, tra cứu chứng từ; đăng nhập | AF5: Link trong danh sách là ảnh captcha, form ở trang gốc tracuu.easyinvoice.vn; mã tra cứu = Fkey; project đã có adapter easyinvoice | AG5: https://tracuu.easyinvoice.vn/Search/Index | AJ5: =IFERROR(IF(INDEX('WBS2'!$I$2:$I$25,MATCH($C5,'WBS2'!$F$2:$F$25,0))="","",INDEX('WBS2'!$I$2:$I$25,MATCH($C5,'WBS2'!$F$2:$F$25,0))),"") -> Hoàn thành | AK5: =IFERROR(IF(INDEX('WBS2'!$I$27:$I$162,MATCH($C5,'WBS2'!$F$27:$F$162,0))="","",INDEX('WBS2'!$I$27:$I$162,MATCH($C5,'WBS2'!$F$27:$F$162,0))),"") -> Hoàn thành | AL5: =IFERROR(IF(OR($AK5="Chưa hoàn thành",$AK5="Sẵn sàng"),INDEX('WBS2'!$H$27:$H$162,MATCH($C5,'WBS2'!$F$27:$F$162,0)),""),"") | AM5: =IFERROR(IF(INDEX('WBS2'!$J$27:$J$162,MATCH($C5,'WBS2'!$F$27:$F$162,0))="","",INDEX('WBS2'!$J$27:$J$162,MATCH($C5,'WBS2'!$F$27:$F$162,0))),"") | AN5: =IFERROR(IF(INDEX('WBS2'!$I$163:$I$298,MATCH($C5,'WBS2'!$F$163:$F$298,0))="","",INDEX('WBS2'!$I$163:$I$298,MATCH($C5,'WBS2'!$F$163:$F$298,0))),"") -> Hoàn thành | AO5: =IFERROR(IF(OR($AN5="Chưa hoàn thành",$AN5="Sẵn sàng"),INDEX('WBS2'!$H$163:$H$298,MATCH($C5,'WBS2'!$F$163:$F$298,0)),""),"") | AP5: =IFERROR(IF(INDEX('WBS2'!$J$163:$J$298,MATCH($C5,'WBS2'!$F$163:$F$298,0))="","",INDEX('WBS2'!$J$163:$J$298,MATCH($C5,'WBS2'!$F$163:$F$298,0))),"")
A6: 5 | B6: Công ty TNHH L.C.S | C6: 0302999571 | D6: Số 102A, Bùi Minnh Trực, phường 6, quận 8, Tp Hồ Chí Minh | E6: https://einvoice.lcs.com.vn | F6: captcha dạng tích | G6: https://eip.lcssoft.com.vn/desktop/#/login | H6: =IF(N6<>"OK","",IF(IF(O6="✓","Mã tra cứu|","")&IF(P6="✓","MST người bán|","")&IF(Q6="✓","MST người mua|","")&IF(R6="✓","Mẫu số / Ký hiệu|","")&IF(S6="✓","Số HĐ|","")&IF(T6="✓","Ngày lập|","")&IF(U6="✓","Tổng tiền|","")&IF(V6="✓","Mã CQT|","")&IF(W6="✓","Upload XML|","")&IF(X6="✓","Captcha ảnh|","")&IF(Y6="✓","Captcha dạng tích|","")&IF(Z6="✓","Captcha khác (slider/hình)|","")&IF(AA6="✓","Đăng nhập|","")&IF(AB6="✓","Email/SĐT/OTP|","")="","(không có tham số)",SUBSTITUTE(LEFT(IF(O6="✓","Mã tra cứu|","")&IF(P6="✓","MST người bán|","")&IF(Q6="✓","MST người mua|","")&IF(R6="✓","Mẫu số / Ký hiệu|","")&IF(S6="✓","Số HĐ|","")&IF(T6="✓","Ngày lập|","")&IF(U6="✓","Tổng tiền|","")&IF(V6="✓","Mã CQT|","")&IF(W6="✓","Upload XML|","")&IF(X6="✓","Captcha ảnh|","")&IF(Y6="✓","Captcha dạng tích|","")&IF(Z6="✓","Captcha khác (slider/hình)|","")&IF(AA6="✓","Đăng nhập|","")&IF(AB6="✓","Email/SĐT/OTP|",""),LEN(IF(O6="✓","Mã tra cứu|","")&IF(P6="✓","MST người bán|","")&IF(Q6="✓","MST người mua|","")&IF(R6="✓","Mẫu số / Ký hiệu|","")&IF(S6="✓","Số HĐ|","")&IF(T6="✓","Ngày lập|","")&IF(U6="✓","Tổng tiền|","")&IF(V6="✓","Mã CQT|","")&IF(W6="✓","Upload XML|","")&IF(X6="✓","Captcha ảnh|","")&IF(Y6="✓","Captcha dạng tích|","")&IF(Z6="✓","Captcha khác (slider/hình)|","")&IF(AA6="✓","Đăng nhập|","")&IF(AB6="✓","Email/SĐT/OTP|",""))-1),"|"," + "))) -> Mã tra cứu + Mẫu số / Ký hiệu + Số HĐ + Captcha dạng tích | N6: OK | O6: ✓ | R6: ✓ | S6: ✓ | Y6: ✓ | AC6: 4 | AD6: reCAPTCHA v2 checkbox | AE6: Link 'Xác thực hóa đơn điện tử' (#/check-signature): upload file XML | AF6: SPA Angular Material; khung tra cứu (mẫu số + ký hiệu + số HĐ + mã hóa đơn) nằm cạnh khung đăng nhập, không cần đăng nhập | AG6: https://eip.lcssoft.com.vn/desktop/#/login | AJ6: =IFERROR(IF(INDEX('WBS2'!$I$2:$I$25,MATCH($C6,'WBS2'!$F$2:$F$25,0))="","",INDEX('WBS2'!$I$2:$I$25,MATCH($C6,'WBS2'!$F$2:$F$25,0))),"") | AK6: =IFERROR(IF(INDEX('WBS2'!$I$27:$I$162,MATCH($C6,'WBS2'!$F$27:$F$162,0))="","",INDEX('WBS2'!$I$27:$I$162,MATCH($C6,'WBS2'!$F$27:$F$162,0))),"") -> Chưa hoàn thành | AL6: =IFERROR(IF(OR($AK6="Chưa hoàn thành",$AK6="Sẵn sàng"),INDEX('WBS2'!$H$27:$H$162,MATCH($C6,'WBS2'!$F$27:$F$162,0)),""),"") -> 46446 | AM6: =IFERROR(IF(INDEX('WBS2'!$J$27:$J$162,MATCH($C6,'WBS2'!$F$27:$F$162,0))="","",INDEX('WBS2'!$J$27:$J$162,MATCH($C6,'WBS2'!$F$27:$F$162,0))),"") -> Không làm được qua link tra cứu – bị chặn bởi reCAPTCHA v2 (server kiểm), lấy qua mail. eip.lcssoft.com.vn | AN6: =IFERROR(IF(INDEX('WBS2'!$I$163:$I$298,MATCH($C6,'WBS2'!$F$163:$F$298,0))="","",INDEX('WBS2'!$I$163:$I$298,MATCH($C6,'WBS2'!$F$163:$F$298,0))),"") -> Chưa hoàn thành | AO6: =IFERROR(IF(OR($AN6="Chưa hoàn thành",$AN6="Sẵn sàng"),INDEX('WBS2'!$H$163:$H$298,MATCH($C6,'WBS2'!$F$163:$F$298,0)),""),"") -> 46446 | AP6: =IFERROR(IF(INDEX('WBS2'!$J$163:$J$298,MATCH($C6,'WBS2'!$F$163:$F$298,0))="","",INDEX('WBS2'!$J$163:$J$298,MATCH($C6,'WBS2'!$F$163:$F$298,0))),"") -> Chưa có mail/PDF nào của NCC này (kiểm DB 27/10)
A7: 6 | B7: Công ty TNHH Soft Ware KK VAT | C7: 0313963672 | D7: 101017/46A Lê Văn Lương, Ấp 3, Xã Phước Kiển, Huyện nhà Bè, Tp Hồ Chí Minh | E7: http://kkvat.com.vn/thongtin | F7: Không có captcha | G7: https://tracuuhoadon.kkvat.com.vn/ | H7: =IF(N7<>"OK","",IF(IF(O7="✓","Mã tra cứu|","")&IF(P7="✓","MST người bán|","")&IF(Q7="✓","MST người mua|","")&IF(R7="✓","Mẫu số / Ký hiệu|","")&IF(S7="✓","Số HĐ|","")&IF(T7="✓","Ngày lập|","")&IF(U7="✓","Tổng tiền|","")&IF(V7="✓","Mã CQT|","")&IF(W7="✓","Upload XML|","")&IF(X7="✓","Captcha ảnh|","")&IF(Y7="✓","Captcha dạng tích|","")&IF(Z7="✓","Captcha khác (slider/hình)|","")&IF(AA7="✓","Đăng nhập|","")&IF(AB7="✓","Email/SĐT/OTP|","")="","(không có tham số)",SUBSTITUTE(LEFT(IF(O7="✓","Mã tra cứu|","")&IF(P7="✓","MST người bán|","")&IF(Q7="✓","MST người mua|","")&IF(R7="✓","Mẫu số / Ký hiệu|","")&IF(S7="✓","Số HĐ|","")&IF(T7="✓","Ngày lập|","")&IF(U7="✓","Tổng tiền|","")&IF(V7="✓","Mã CQT|","")&IF(W7="✓","Upload XML|","")&IF(X7="✓","Captcha ảnh|","")&IF(Y7="✓","Captcha dạng tích|","")&IF(Z7="✓","Captcha khác (slider/hình)|","")&IF(AA7="✓","Đăng nhập|","")&IF(AB7="✓","Email/SĐT/OTP|",""),LEN(IF(O7="✓","Mã tra cứu|","")&IF(P7="✓","MST người bán|","")&IF(Q7="✓","MST người mua|","")&IF(R7="✓","Mẫu số / Ký hiệu|","")&IF(S7="✓","Số HĐ|","")&IF(T7="✓","Ngày lập|","")&IF(U7="✓","Tổng tiền|","")&IF(V7="✓","Mã CQT|","")&IF(W7="✓","Upload XML|","")&IF(X7="✓","Captcha ảnh|","")&IF(Y7="✓","Captcha dạng tích|","")&IF(Z7="✓","Captcha khác (slider/hình)|","")&IF(AA7="✓","Đăng nhập|","")&IF(AB7="✓","Email/SĐT/OTP|",""))-1),"|"," + "))) -> Mã tra cứu + MST người mua | N7: OK | O7: ✓ | Q7: ✓ | AC7: 2 | AD7: không có | AF7: Ô MST ghi 'Mã số thuế đơn vị nhận' (bên mua), không phải MST bên bán | AG7: https://tracuuhoadon.kkvat.com.vn/ | AJ7: =IFERROR(IF(INDEX('WBS2'!$I$2:$I$25,MATCH($C7,'WBS2'!$F$2:$F$25,0))="","",INDEX('WBS2'!$I$2:$I$25,MATCH($C7,'WBS2'!$F$2:$F$25,0))),"") | AK7: =IFERROR(IF(INDEX('WBS2'!$I$27:$I$162,MATCH($C7,'WBS2'!$F$27:$F$162,0))="","",INDEX('WBS2'!$I$27:$I$162,MATCH($C7,'WBS2'!$F$27:$F$162,0))),"") -> Sẵn sàng | AL7: =IFERROR(IF(OR($AK7="Chưa hoàn thành",$AK7="Sẵn sàng"),INDEX('WBS2'!$H$27:$H$162,MATCH($C7,'WBS2'!$F$27:$F$162,0)),""),"") -> 46356 | AM7: =IFERROR(IF(INDEX('WBS2'!$J$27:$J$162,MATCH($C7,'WBS2'!$F$27:$F$162,0))="","",INDEX('WBS2'!$J$27:$J$162,MATCH($C7,'WBS2'!$F$27:$F$162,0))),"") | AN7: =IFERROR(IF(INDEX('WBS2'!$I$163:$I$298,MATCH($C7,'WBS2'!$F$163:$F$298,0))="","",INDEX('WBS2'!$I$163:$I$298,MATCH($C7,'WBS2'!$F$163:$F$298,0))),"") -> Chưa hoàn thành | AO7: =IFERROR(IF(OR($AN7="Chưa hoàn thành",$AN7="Sẵn sàng"),INDEX('WBS2'!$H$163:$H$298,MATCH($C7,'WBS2'!$F$163:$F$298,0)),""),"") -> 46446 | AP7: =IFERROR(IF(INDEX('WBS2'!$J$163:$J$298,MATCH($C7,'WBS2'!$F$163:$F$298,0))="","",INDEX('WBS2'!$J$163:$J$298,MATCH($C7,'WBS2'!$F$163:$F$298,0))),"") -> Chưa có mail/PDF nào của NCC này (kiểm DB 27/10)
A8: 7 | B8: Công ty Cổ phần CyberLotus | C8: 0105232093 | E8: https://tracuuhoadon2.xcyber.vn/#/tracuuhoadon/tracuu | F8: có captcha | G8: https://tracuuhoadon2.xcyber.vn/#/tracuuhoadon/tracuu | H8: =IF(N8<>"OK","",IF(IF(O8="✓","Mã tra cứu|","")&IF(P8="✓","MST người bán|","")&IF(Q8="✓","MST người mua|","")&IF(R8="✓","Mẫu số / Ký hiệu|","")&IF(S8="✓","Số HĐ|","")&IF(T8="✓","Ngày lập|","")&IF(U8="✓","Tổng tiền|","")&IF(V8="✓","Mã CQT|","")&IF(W8="✓","Upload XML|","")&IF(X8="✓","Captcha ảnh|","")&IF(Y8="✓","Captcha dạng tích|","")&IF(Z8="✓","Captcha khác (slider/hình)|","")&IF(AA8="✓","Đăng nhập|","")&IF(AB8="✓","Email/SĐT/OTP|","")="","(không có tham số)",SUBSTITUTE(LEFT(IF(O8="✓","Mã tra cứu|","")&IF(P8="✓","MST người bán|","")&IF(Q8="✓","MST người mua|","")&IF(R8="✓","Mẫu số / Ký hiệu|","")&IF(S8="✓","Số HĐ|","")&IF(T8="✓","Ngày lập|","")&IF(U8="✓","Tổng tiền|","")&IF(V8="✓","Mã CQT|","")&IF(W8="✓","Upload XML|","")&IF(X8="✓","Captcha ảnh|","")&IF(Y8="✓","Captcha dạng tích|","")&IF(Z8="✓","Captcha khác (slider/hình)|","")&IF(AA8="✓","Đăng nhập|","")&IF(AB8="✓","Email/SĐT/OTP|",""),LEN(IF(O8="✓","Mã tra cứu|","")&IF(P8="✓","MST người bán|","")&IF(Q8="✓","MST người mua|","")&IF(R8="✓","Mẫu số / Ký hiệu|","")&IF(S8="✓","Số HĐ|","")&IF(T8="✓","Ngày lập|","")&IF(U8="✓","Tổng tiền|","")&IF(V8="✓","Mã CQT|","")&IF(W8="✓","Upload XML|","")&IF(X8="✓","Captcha ảnh|","")&IF(Y8="✓","Captcha dạng tích|","")&IF(Z8="✓","Captcha khác (slider/hình)|","")&IF(AA8="✓","Đăng nhập|","")&IF(AB8="✓","Email/SĐT/OTP|",""))-1),"|"," + "))) -> Mã tra cứu + Captcha ảnh | I8: Xong | K8: 0.977 | L8: g_300x75 | N8: OK | O8: ✓ | X8: ✓ | AC8: 2 | AD8: ảnh 300x75 base64 (API bill2app.xcyber.vn/.../TraCuuHoaDon/RefreshCaptcha), 5 chữ số màu có gạch nhiễu, hiển thị 180x45 | AE8: 'Xác thực hóa đơn' (#/tracuuhoadon/xacthuc): chọn file XML + chọn mẫu thông tư + captcha ảnh; 'Link dự phòng' tracuuhoadon.cyberbill.vn | AF8: SPA (Angular/ABP). Ô MaSoBiMat ('mã tra cứu') + mã xác thực. Trang nạp recaptcha/api.js nhưng không có widget. Nhóm model g_300x75. | AG8: https://tracuuhoadon2.xcyber.vn/#/tracuuhoadon/tracuu | AJ8: =IFERROR(IF(INDEX('WBS2'!$I$2:$I$25,MATCH($C8,'WBS2'!$F$2:$F$25,0))="","",INDEX('WBS2'!$I$2:$I$25,MATCH($C8,'WBS2'!$F$2:$F$25,0))),"") -> Hoàn thành | AK8: =IFERROR(IF(INDEX('WBS2'!$I$27:$I$162,MATCH($C8,'WBS2'!$F$27:$F$162,0))="","",INDEX('WBS2'!$I$27:$I$162,MATCH($C8,'WBS2'!$F$27:$F$162,0))),"") -> Hoàn thành | AL8: =IFERROR(IF(OR($AK8="Chưa hoàn thành",$AK8="Sẵn sàng"),INDEX('WBS2'!$H$27:$H$162,MATCH($C8,'WBS2'!$F$27:$F$162,0)),""),"") | AM8: =IFERROR(IF(INDEX('WBS2'!$J$27:$J$162,MATCH($C8,'WBS2'!$F$27:$F$162,0))="","",INDEX('WBS2'!$J$27:$J$162,MATCH($C8,'WBS2'!$F$27:$F$162,0))),"") | AN8: =IFERROR(IF(INDEX('WBS2'!$I$163:$I$298,MATCH($C8,'WBS2'!$F$163:$F$298,0))="","",INDEX('WBS2'!$I$163:$I$298,MATCH($C8,'WBS2'!$F$163:$F$298,0))),"") -> Sẵn sàng | AO8: =IFERROR(IF(OR($AN8="Chưa hoàn thành",$AN8="Sẵn sàng"),INDEX('WBS2'!$H$163:$H$298,MATCH($C8,'WBS2'!$F$163:$F$298,0)),""),"") -> 46356 | AP8: =IFERROR(IF(INDEX('WBS2'!$J$163:$J$298,MATCH($C8,'WBS2'!$F$163:$F$298,0))="","",INDEX('WBS2'!$J$163:$J$298,MATCH($C8,'WBS2'!$F$163:$F$298,0))),"")
A9: 8 | B9: Công ty TNHH Giải pháp công nghệ Ngô Gia Phát | C9: 0311942758 | D9: Số 1134/16/2/13 Nguyễn Văn Quá, phường Đông Hưng Thuận, quận 12, Tp Hồ Chí Minh | E9: http://www.ngogiaphat.vn | F9: có captcha | G9: https://tracuuonline.ngogiaphat.vn/Search.aspx | H9: =IF(N9<>"OK","",IF(IF(O9="✓","Mã tra cứu|","")&IF(P9="✓","MST người bán|","")&IF(Q9="✓","MST người mua|","")&IF(R9="✓","Mẫu số / Ký hiệu|","")&IF(S9="✓","Số HĐ|","")&IF(T9="✓","Ngày lập|","")&IF(U9="✓","Tổng tiền|","")&IF(V9="✓","Mã CQT|","")&IF(W9="✓","Upload XML|","")&IF(X9="✓","Captcha ảnh|","")&IF(Y9="✓","Captcha dạng tích|","")&IF(Z9="✓","Captcha khác (slider/hình)|","")&IF(AA9="✓","Đăng nhập|","")&IF(AB9="✓","Email/SĐT/OTP|","")="","(không có tham số)",SUBSTITUTE(LEFT(IF(O9="✓","Mã tra cứu|","")&IF(P9="✓","MST người bán|","")&IF(Q9="✓","MST người mua|","")&IF(R9="✓","Mẫu số / Ký hiệu|","")&IF(S9="✓","Số HĐ|","")&IF(T9="✓","Ngày lập|","")&IF(U9="✓","Tổng tiền|","")&IF(V9="✓","Mã CQT|","")&IF(W9="✓","Upload XML|","")&IF(X9="✓","Captcha ảnh|","")&IF(Y9="✓","Captcha dạng tích|","")&IF(Z9="✓","Captcha khác (slider/hình)|","")&IF(AA9="✓","Đăng nhập|","")&IF(AB9="✓","Email/SĐT/OTP|",""),LEN(IF(O9="✓","Mã tra cứu|","")&IF(P9="✓","MST người bán|","")&IF(Q9="✓","MST người mua|","")&IF(R9="✓","Mẫu số / Ký hiệu|","")&IF(S9="✓","Số HĐ|","")&IF(T9="✓","Ngày lập|","")&IF(U9="✓","Tổng tiền|","")&IF(V9="✓","Mã CQT|","")&IF(W9="✓","Upload XML|","")&IF(X9="✓","Captcha ảnh|","")&IF(Y9="✓","Captcha dạng tích|","")&IF(Z9="✓","Captcha khác (slider/hình)|","")&IF(AA9="✓","Đăng nhập|","")&IF(AB9="✓","Email/SĐT/OTP|",""))-1),"|"," + "))) -> Mã tra cứu + Captcha ảnh | I9: Xong | K9: 0 | L9: g_200x80 | M9: https://tracuuonline.ngogiaphat.vn/DXB.axd?DXCache=db6b00ec-9728-fe9e-c65d-24724858e745 | N9: OK | O9: ✓ | X9: ✓ | AC9: 2 | AD9: ảnh DevExpress ASPxCaptcha 200x80 (hiển thị 200x50, chữ thường + số) | AF9: 1 ô tìm không nhãn (tự viết hoa) — đoán là mã tra cứu; ASP.NET WebForms DevExpress | AG9: https://tracuuonline.ngogiaphat.vn/Search.aspx | AJ9: =IFERROR(IF(INDEX('WBS2'!$I$2:$I$25,MATCH($C9,'WBS2'!$F$2:$F$25,0))="","",INDEX('WBS2'!$I$2:$I$25,MATCH($C9,'WBS2'!$F$2:$F$25,0))),"") -> Hoàn thành | AK9: =IFERROR(IF(INDEX('WBS2'!$I$27:$I$162,MATCH($C9,'WBS2'!$F$27:$F$162,0))="","",INDEX('WBS2'!$I$27:$I$162,MATCH($C9,'WBS2'!$F$27:$F$162,0))),"") -> Chưa hoàn thành | AL9: =IFERROR(IF(OR($AK9="Chưa hoàn thành",$AK9="Sẵn sàng"),INDEX('WBS2'!$H$27:$H$162,MATCH($C9,'WBS2'!$F$27:$F$162,0)),""),"") -> 46446 | AM9: =IFERROR(IF(INDEX('WBS2'!$J$27:$J$162,MATCH($C9,'WBS2'!$F$27:$F$162,0))="","",INDEX('WBS2'!$J$27:$J$162,MATCH($C9,'WBS2'!$F$27:$F$162,0))),"") | AN9: =IFERROR(IF(INDEX('WBS2'!$I$163:$I$298,MATCH($C9,'WBS2'!$F$163:$F$298,0))="","",INDEX('WBS2'!$I$163:$I$298,MATCH($C9,'WBS2'!$F$163:$F$298,0))),"") -> Chưa hoàn thành | AO9: =IFERROR(IF(OR($AN9="Chưa hoàn thành",$AN9="Sẵn sàng"),INDEX('WBS2'!$H$163:$H$298,MATCH($C9,'WBS2'!$F$163:$F$298,0)),""),"") -> 46446 | AP9: =IFERROR(IF(INDEX('WBS2'!$J$163:$J$298,MATCH($C9,'WBS2'!$F$163:$F$298,0))="","",INDEX('WBS2'!$J$163:$J$298,MATCH($C9,'WBS2'!$F$163:$F$298,0))),"") -> Chưa có mail/PDF nào của NCC này (kiểm DB 27/10)
A10: 9 | B10: Công ty Cổ phần Mắt Bão | C10: 0302712571 | D10: 12A Núi Thành, phường 13, quận Tân Bình, Tp Hồ Chí Minh | E10: https://matbao.in | F10: không có captcha | G10: https://matbao.in/tra-cuu-hoa-don | H10: =IF(N10<>"OK","",IF(IF(O10="✓","Mã tra cứu|","")&IF(P10="✓","MST người bán|","")&IF(Q10="✓","MST người mua|","")&IF(R10="✓","Mẫu số / Ký hiệu|","")&IF(S10="✓","Số HĐ|","")&IF(T10="✓","Ngày lập|","")&IF(U10="✓","Tổng tiền|","")&IF(V10="✓","Mã CQT|","")&IF(W10="✓","Upload XML|","")&IF(X10="✓","Captcha ảnh|","")&IF(Y10="✓","Captcha dạng tích|","")&IF(Z10="✓","Captcha khác (slider/hình)|","")&IF(AA10="✓","Đăng nhập|","")&IF(AB10="✓","Email/SĐT/OTP|","")="","(không có tham số)",SUBSTITUTE(LEFT(IF(O10="✓","Mã tra cứu|","")&IF(P10="✓","MST người bán|","")&IF(Q10="✓","MST người mua|","")&IF(R10="✓","Mẫu số / Ký hiệu|","")&IF(S10="✓","Số HĐ|","")&IF(T10="✓","Ngày lập|","")&IF(U10="✓","Tổng tiền|","")&IF(V10="✓","Mã CQT|","")&IF(W10="✓","Upload XML|","")&IF(X10="✓","Captcha ảnh|","")&IF(Y10="✓","Captcha dạng tích|","")&IF(Z10="✓","Captcha khác (slider/hình)|","")&IF(AA10="✓","Đăng nhập|","")&IF(AB10="✓","Email/SĐT/OTP|",""),LEN(IF(O10="✓","Mã tra cứu|","")&IF(P10="✓","MST người bán|","")&IF(Q10="✓","MST người mua|","")&IF(R10="✓","Mẫu số / Ký hiệu|","")&IF(S10="✓","Số HĐ|","")&IF(T10="✓","Ngày lập|","")&IF(U10="✓","Tổng tiền|","")&IF(V10="✓","Mã CQT|","")&IF(W10="✓","Upload XML|","")&IF(X10="✓","Captcha ảnh|","")&IF(Y10="✓","Captcha dạng tích|","")&IF(Z10="✓","Captcha khác (slider/hình)|","")&IF(AA10="✓","Đăng nhập|","")&IF(AB10="✓","Email/SĐT/OTP|",""))-1),"|"," + "))) -> Mã tra cứu | N10: OK | O10: ✓ | AC10: 1 | AD10: không có | AE10: Tab 'Tra cứu dùng file XML': upload .xml | AF10: Chỉ cần mã tra cứu | AG10: https://matbao.in/tra-cuu-hoa-don | AJ10: =IFERROR(IF(INDEX('WBS2'!$I$2:$I$25,MATCH($C10,'WBS2'!$F$2:$F$25,0))="","",INDEX('WBS2'!$I$2:$I$25,MATCH($C10,'WBS2'!$F$2:$F$25,0))),"") | AK10: =IFERROR(IF(INDEX('WBS2'!$I$27:$I$162,MATCH($C10,'WBS2'!$F$27:$F$162,0))="","",INDEX('WBS2'!$I$27:$I$162,MATCH($C10,'WBS2'!$F$27:$F$162,0))),"") -> Hoàn thành | AL10: =IFERROR(IF(OR($AK10="Chưa hoàn thành",$AK10="Sẵn sàng"),INDEX('WBS2'!$H$27:$H$162,MATCH($C10,'WBS2'!$F$27:$F$162,0)),""),"") | AM10: =IFERROR(IF(INDEX('WBS2'!$J$27:$J$162,MATCH($C10,'WBS2'!$F$27:$F$162,0))="","",INDEX('WBS2'!$J$27:$J$162,MATCH($C10,'WBS2'!$F$27:$F$162,0))),"") | AN10: =IFERROR(IF(INDEX('WBS2'!$I$163:$I$298,MATCH($C10,'WBS2'!$F$163:$F$298,0))="","",INDEX('WBS2'!$I$163:$I$298,MATCH($C10,'WBS2'!$F$163:$F$298,0))),"") -> Hoàn thành | AO10: =IFERROR(IF(OR($AN10="Chưa hoàn thành",$AN10="Sẵn sàng"),INDEX('WBS2'!$H$163:$H$298,MATCH($C10,'WBS2'!$F$163:$F$298,0)),""),"") | AP10: =IFERROR(IF(INDEX('WBS2'!$J$163:$J$298,MATCH($C10,'WBS2'!$F$163:$F$298,0))="","",INDEX('WBS2'!$J$163:$J$298,MATCH($C10,'WBS2'!$F$163:$F$298,0))),"")
A11: 10 | B11: Công ty Cổ phần công nghệ thẻ Nacencomm | C11: 0103930279 | D11: Tầng 5, số 2 Chùa Bộc, phường Trung Tự, quận Đống Đa, Tp Hà Nội | E11: https://www.nacencomm.com.vn/dich-vu-chi-tiet/hoa-don-dien-tu | F11: Không có captcha | G11: https://hoadon78.nacencomm.vn/tracuuhd.aspx | H11: =IF(N11<>"OK","",IF(IF(O11="✓","Mã tra cứu|","")&IF(P11="✓","MST người bán|","")&IF(Q11="✓","MST người mua|","")&IF(R11="✓","Mẫu số / Ký hiệu|","")&IF(S11="✓","Số HĐ|","")&IF(T11="✓","Ngày lập|","")&IF(U11="✓","Tổng tiền|","")&IF(V11="✓","Mã CQT|","")&IF(W11="✓","Upload XML|","")&IF(X11="✓","Captcha ảnh|","")&IF(Y11="✓","Captcha dạng tích|","")&IF(Z11="✓","Captcha khác (slider/hình)|","")&IF(AA11="✓","Đăng nhập|","")&IF(AB11="✓","Email/SĐT/OTP|","")="","(không có tham số)",SUBSTITUTE(LEFT(IF(O11="✓","Mã tra cứu|","")&IF(P11="✓","MST người bán|","")&IF(Q11="✓","MST người mua|","")&IF(R11="✓","Mẫu số / Ký hiệu|","")&IF(S11="✓","Số HĐ|","")&IF(T11="✓","Ngày lập|","")&IF(U11="✓","Tổng tiền|","")&IF(V11="✓","Mã CQT|","")&IF(W11="✓","Upload XML|","")&IF(X11="✓","Captcha ảnh|","")&IF(Y11="✓","Captcha dạng tích|","")&IF(Z11="✓","Captcha khác (slider/hình)|","")&IF(AA11="✓","Đăng nhập|","")&IF(AB11="✓","Email/SĐT/OTP|",""),LEN(IF(O11="✓","Mã tra cứu|","")&IF(P11="✓","MST người bán|","")&IF(Q11="✓","MST người mua|","")&IF(R11="✓","Mẫu số / Ký hiệu|","")&IF(S11="✓","Số HĐ|","")&IF(T11="✓","Ngày lập|","")&IF(U11="✓","Tổng tiền|","")&IF(V11="✓","Mã CQT|","")&IF(W11="✓","Upload XML|","")&IF(X11="✓","Captcha ảnh|","")&IF(Y11="✓","Captcha dạng tích|","")&IF(Z11="✓","Captcha khác (slider/hình)|","")&IF(AA11="✓","Đăng nhập|","")&IF(AB11="✓","Email/SĐT/OTP|",""))-1),"|"," + "))) -> Mã tra cứu | N11: OK | O11: ✓ | AC11: 1 | AD11: không có | AE11: Radio 'Theo chuỗi xác thực': 1 ô chuỗi xác thực; tab 'Chứng từ TNCN'; trong HTML còn panel ẩn (không có nút chọn trên UI): MST + mẫu số + ký hiệu + số HĐ + ngày HĐ + giá trị | AF11: Ô mặc định: 'Nhập mã tra cứu hoặc số hóa đơn và 4 ký tự đầu của chuỗi xác thực'; DevExpress WebForms; ô MST người mua chỉ hiện sau khi tìm thấy (để ký HĐ bên mua) | AG11: https://hoadon78.nacencomm.vn/tracuuhd.aspx | AJ11: =IFERROR(IF(INDEX('WBS2'!$I$2:$I$25,MATCH($C11,'WBS2'!$F$2:$F$25,0))="","",INDEX('WBS2'!$I$2:$I$25,MATCH($C11,'WBS2'!$F$2:$F$25,0))),"") | AK11: =IFERROR(IF(INDEX('WBS2'!$I$27:$I$162,MATCH($C11,'WBS2'!$F$27:$F$162,0))="","",INDEX('WBS2'!$I$27:$I$162,MATCH($C11,'WBS2'!$F$27:$F$162,0))),"") -> Sẵn sàng | AL11: =IFERROR(IF(OR($AK11="Chưa hoàn thành",$AK11="Sẵn sàng"),INDEX('WBS2'!$H$27:$H$162,MATCH($C11,'WBS2'!$F$27:$F$162,0)),""),"") -> 46356 | AM11: =IFERROR(IF(INDEX('WBS2'!$J$27:$J$162,MATCH($C11,'WBS2'!$F$27:$F$162,0))="","",INDEX('WBS2'!$J$27:$J$162,MATCH($C11,'WBS2'!$F$27:$F$162,0))),"") | AN11: =IFERROR(IF(INDEX('WBS2'!$I$163:$I$298,MATCH($C11,'WBS2'!$F$163:$F$298,0))="","",INDEX('WBS2'!$I$163:$I$298,MATCH($C11,'WBS2'!$F$163:$F$298,0))),"") -> Chưa hoàn thành | AO11: =IFERROR(IF(OR($AN11="Chưa hoàn thành",$AN11="Sẵn sàng"),INDEX('WBS2'!$H$163:$H$298,MATCH($C11,'WBS2'!$F$163:$F$298,0)),""),"") -> 46446 | AP11: =IFERROR(IF(INDEX('WBS2'!$J$163:$J$298,MATCH($C11,'WBS2'!$F$163:$F$298,0))="","",INDEX('WBS2'!$J$163:$J$298,MATCH($C11,'WBS2'!$F$163:$F$298,0))),"") -> Chưa có mail/PDF nào của NCC này (kiểm DB 27/10)
A12: 11 | B12: Công ty Cổ phần Megabiz Việt Nam | C12: 0105844836 | D12: Số 3 ngõ 15 đường Nghĩa Dũng, phường Phúc Xá, quận Ba Đình, Tp Hà Nội | E12: https://vinvoice.vn | F12: có captcha | G12: https://tracuu.vinvoice.vn/Captcha/Show | H12: =IF(N12<>"OK","",IF(IF(O12="✓","Mã tra cứu|","")&IF(P12="✓","MST người bán|","")&IF(Q12="✓","MST người mua|","")&IF(R12="✓","Mẫu số / Ký hiệu|","")&IF(S12="✓","Số HĐ|","")&IF(T12="✓","Ngày lập|","")&IF(U12="✓","Tổng tiền|","")&IF(V12="✓","Mã CQT|","")&IF(W12="✓","Upload XML|","")&IF(X12="✓","Captcha ảnh|","")&IF(Y12="✓","Captcha dạng tích|","")&IF(Z12="✓","Captcha khác (slider/hình)|","")&IF(AA12="✓","Đăng nhập|","")&IF(AB12="✓","Email/SĐT/OTP|","")="","(không có tham số)",SUBSTITUTE(LEFT(IF(O12="✓","Mã tra cứu|","")&IF(P12="✓","MST người bán|","")&IF(Q12="✓","MST người mua|","")&IF(R12="✓","Mẫu số / Ký hiệu|","")&IF(S12="✓","Số HĐ|","")&IF(T12="✓","Ngày lập|","")&IF(U12="✓","Tổng tiền|","")&IF(V12="✓","Mã CQT|","")&IF(W12="✓","Upload XML|","")&IF(X12="✓","Captcha ảnh|","")&IF(Y12="✓","Captcha dạng tích|","")&IF(Z12="✓","Captcha khác (slider/hình)|","")&IF(AA12="✓","Đăng nhập|","")&IF(AB12="✓","Email/SĐT/OTP|",""),LEN(IF(O12="✓","Mã tra cứu|","")&IF(P12="✓","MST người bán|","")&IF(Q12="✓","MST người mua|","")&IF(R12="✓","Mẫu số / Ký hiệu|","")&IF(S12="✓","Số HĐ|","")&IF(T12="✓","Ngày lập|","")&IF(U12="✓","Tổng tiền|","")&IF(V12="✓","Mã CQT|","")&IF(W12="✓","Upload XML|","")&IF(X12="✓","Captcha ảnh|","")&IF(Y12="✓","Captcha dạng tích|","")&IF(Z12="✓","Captcha khác (slider/hình)|","")&IF(AA12="✓","Đăng nhập|","")&IF(AB12="✓","Email/SĐT/OTP|",""))-1),"|"," + "))) -> Mã tra cứu + Captcha ảnh | I12: Xong | K12: 1 | L12: g_120x38 | N12: OK | O12: ✓ | X12: ✓ | AC12: 2 | AD12: ảnh 120x38 (/Captcha/Show, hiển thị 110x35) | AE12: Menu khác: Chứng từ khấu trừ TNCN, Biên lai, Biên bản; link 'Tra cứu hóa đơn TT32' | AF12: Link trong danh sách là ảnh captcha, form ở trang gốc; chỉ mã tra cứu + captcha | AG12: https://tracuu.vinvoice.vn/ | AJ12: =IFERROR(IF(INDEX('WBS2'!$I$2:$I$25,MATCH($C12,'WBS2'!$F$2:$F$25,0))="","",INDEX('WBS2'!$I$2:$I$25,MATCH($C12,'WBS2'!$F$2:$F$25,0))),"") -> Hoàn thành | AK12: =IFERROR(IF(INDEX('WBS2'!$I$27:$I$162,MATCH($C12,'WBS2'!$F$27:$F$162,0))="","",INDEX('WBS2'!$I$27:$I$162,MATCH($C12,'WBS2'!$F$27:$F$162,0))),"") -> Sẵn sàng | AL12: =IFERROR(IF(OR($AK12="Chưa hoàn thành",$AK12="Sẵn sàng"),INDEX('WBS2'!$H$27:$H$162,MATCH($C12,'WBS2'!$F$27:$F$162,0)),""),"") -> 46356 | AM12: =IFERROR(IF(INDEX('WBS2'!$J$27:$J$162,MATCH($C12,'WBS2'!$F$27:$F$162,0))="","",INDEX('WBS2'!$J$27:$J$162,MATCH($C12,'WBS2'!$F$27:$F$162,0))),"") | AN12: =IFERROR(IF(INDEX('WBS2'!$I$163:$I$298,MATCH($C12,'WBS2'!$F$163:$F$298,0))="","",INDEX('WBS2'!$I$163:$I$298,MATCH($C12,'WBS2'!$F$163:$F$298,0))),"") -> Sẵn sàng | AO12: =IFERROR(IF(OR($AN12="Chưa hoàn thành",$AN12="Sẵn sàng"),INDEX('WBS2'!$H$163:$H$298,MATCH($C12,'WBS2'!$F$163:$F$298,0)),""),"") -> 46356 | AP12: =IFERROR(IF(INDEX('WBS2'!$J$163:$J$298,MATCH($C12,'WBS2'!$F$163:$F$298,0))="","",INDEX('WBS2'!$J$163:$J$298,MATCH($C12,'WBS2'!$F$163:$F$298,0))),"")
A13: 12 | B13: Công ty TNHH Công nghệ LCD Việt Nam | C13: 0312483391 | D13: 26/1 Trần Quang Khải, phường Tân Định, quận 1, Tp Hồ Chí Minh | E13: https://azinvoice.com | F13: không có thông tin | G13: https://azinvoice.vn/#/search-xml | H13: =IF(N13<>"OK","",IF(IF(O13="✓","Mã tra cứu|","")&IF(P13="✓","MST người bán|","")&IF(Q13="✓","MST người mua|","")&IF(R13="✓","Mẫu số / Ký hiệu|","")&IF(S13="✓","Số HĐ|","")&IF(T13="✓","Ngày lập|","")&IF(U13="✓","Tổng tiền|","")&IF(V13="✓","Mã CQT|","")&IF(W13="✓","Upload XML|","")&IF(X13="✓","Captcha ảnh|","")&IF(Y13="✓","Captcha dạng tích|","")&IF(Z13="✓","Captcha khác (slider/hình)|","")&IF(AA13="✓","Đăng nhập|","")&IF(AB13="✓","Email/SĐT/OTP|","")="","(không có tham số)",SUBSTITUTE(LEFT(IF(O13="✓","Mã tra cứu|","")&IF(P13="✓","MST người bán|","")&IF(Q13="✓","MST người mua|","")&IF(R13="✓","Mẫu số / Ký hiệu|","")&IF(S13="✓","Số HĐ|","")&IF(T13="✓","Ngày lập|","")&IF(U13="✓","Tổng tiền|","")&IF(V13="✓","Mã CQT|","")&IF(W13="✓","Upload XML|","")&IF(X13="✓","Captcha ảnh|","")&IF(Y13="✓","Captcha dạng tích|","")&IF(Z13="✓","Captcha khác (slider/hình)|","")&IF(AA13="✓","Đăng nhập|","")&IF(AB13="✓","Email/SĐT/OTP|",""),LEN(IF(O13="✓","Mã tra cứu|","")&IF(P13="✓","MST người bán|","")&IF(Q13="✓","MST người mua|","")&IF(R13="✓","Mẫu số / Ký hiệu|","")&IF(S13="✓","Số HĐ|","")&IF(T13="✓","Ngày lập|","")&IF(U13="✓","Tổng tiền|","")&IF(V13="✓","Mã CQT|","")&IF(W13="✓","Upload XML|","")&IF(X13="✓","Captcha ảnh|","")&IF(Y13="✓","Captcha dạng tích|","")&IF(Z13="✓","Captcha khác (slider/hình)|","")&IF(AA13="✓","Đăng nhập|","")&IF(AB13="✓","Email/SĐT/OTP|",""))-1),"|"," + "))) | N13: Faile | AD13: không xác định | AF13: azinvoice.vn: DNS không phân giải (ERR_NAME_NOT_RESOLVED); web azinvoice.com: tên miền đã hết hạn (trang NameBright) | AG13: https://azinvoice.vn/#/search-xml | AJ13: =IFERROR(IF(INDEX('WBS2'!$I$2:$I$25,MATCH($C13,'WBS2'!$F$2:$F$25,0))="","",INDEX('WBS2'!$I$2:$I$25,MATCH($C13,'WBS2'!$F$2:$F$25,0))),"") | AK13: =IFERROR(IF(INDEX('WBS2'!$I$27:$I$162,MATCH($C13,'WBS2'!$F$27:$F$162,0))="","",INDEX('WBS2'!$I$27:$I$162,MATCH($C13,'WBS2'!$F$27:$F$162,0))),"") -> Chưa hoàn thành | AL13: =IFERROR(IF(OR($AK13="Chưa hoàn thành",$AK13="Sẵn sàng"),INDEX('WBS2'!$H$27:$H$162,MATCH($C13,'WBS2'!$F$27:$F$162,0)),""),"") -> 46446 | AM13: =IFERROR(IF(INDEX('WBS2'!$J$27:$J$162,MATCH($C13,'WBS2'!$F$27:$F$162,0))="","",INDEX('WBS2'!$J$27:$J$162,MATCH($C13,'WBS2'!$F$27:$F$162,0))),"") -> Không làm được qua link tra cứu – cổng lỗi. azinvoice.vn (khảo sát 14/10: Faile) | AN13: =IFERROR(IF(INDEX('WBS2'!$I$163:$I$298,MATCH($C13,'WBS2'!$F$163:$F$298,0))="","",INDEX('WBS2'!$I$163:$I$298,MATCH($C13,'WBS2'!$F$163:$F$298,0))),"") -> Chưa hoàn thành | AO13: =IFERROR(IF(OR($AN13="Chưa hoàn thành",$AN13="Sẵn sàng"),INDEX('WBS2'!$H$163:$H$298,MATCH($C13,'WBS2'!$F$163:$F$298,0)),""),"") -> 46446 | AP13: =IFERROR(IF(INDEX('WBS2'!$J$163:$J$298,MATCH($C13,'WBS2'!$F$163:$F$298,0))="","",INDEX('WBS2'!$J$163:$J$298,MATCH($C13,'WBS2'!$F$163:$F$298,0))),"") -> Chưa có mail/PDF nào của NCC này (kiểm DB 27/10)
A14: 13 | B14: Công ty Cổ phần MISA | C14: 0101243150 | D14: Tầng 9, tòa nhà Technosoft, phố Duy Tân, phường Dịch Vọng Hậu, quận Cầu Giấy, Tp Hà Nội | E14: https://www.meinvoice.vn/ | F14: Không có captcha | G14: https://www.meinvoice.vn/tra-cuu/ | H14: =IF(N14<>"OK","",IF(IF(O14="✓","Mã tra cứu|","")&IF(P14="✓","MST người bán|","")&IF(Q14="✓","MST người mua|","")&IF(R14="✓","Mẫu số / Ký hiệu|","")&IF(S14="✓","Số HĐ|","")&IF(T14="✓","Ngày lập|","")&IF(U14="✓","Tổng tiền|","")&IF(V14="✓","Mã CQT|","")&IF(W14="✓","Upload XML|","")&IF(X14="✓","Captcha ảnh|","")&IF(Y14="✓","Captcha dạng tích|","")&IF(Z14="✓","Captcha khác (slider/hình)|","")&IF(AA14="✓","Đăng nhập|","")&IF(AB14="✓","Email/SĐT/OTP|","")="","(không có tham số)",SUBSTITUTE(LEFT(IF(O14="✓","Mã tra cứu|","")&IF(P14="✓","MST người bán|","")&IF(Q14="✓","MST người mua|","")&IF(R14="✓","Mẫu số / Ký hiệu|","")&IF(S14="✓","Số HĐ|","")&IF(T14="✓","Ngày lập|","")&IF(U14="✓","Tổng tiền|","")&IF(V14="✓","Mã CQT|","")&IF(W14="✓","Upload XML|","")&IF(X14="✓","Captcha ảnh|","")&IF(Y14="✓","Captcha dạng tích|","")&IF(Z14="✓","Captcha khác (slider/hình)|","")&IF(AA14="✓","Đăng nhập|","")&IF(AB14="✓","Email/SĐT/OTP|",""),LEN(IF(O14="✓","Mã tra cứu|","")&IF(P14="✓","MST người bán|","")&IF(Q14="✓","MST người mua|","")&IF(R14="✓","Mẫu số / Ký hiệu|","")&IF(S14="✓","Số HĐ|","")&IF(T14="✓","Ngày lập|","")&IF(U14="✓","Tổng tiền|","")&IF(V14="✓","Mã CQT|","")&IF(W14="✓","Upload XML|","")&IF(X14="✓","Captcha ảnh|","")&IF(Y14="✓","Captcha dạng tích|","")&IF(Z14="✓","Captcha khác (slider/hình)|","")&IF(AA14="✓","Đăng nhập|","")&IF(AB14="✓","Email/SĐT/OTP|",""))-1),"|"," + "))) -> Mã tra cứu | N14: OK | O14: ✓ | AC14: 1 | AD14: mặc định không có; captcha ảnh ẩn (#captchaContainer, ImageHandler.ashx ~115x30) chỉ hiện sau nhiều lần tìm sai | AE14: Tab 'Theo file xml': upload XML ≤2MB; tab 'Theo email/số điện thoại': chuyển sang đăng nhập MISA ID (email/SĐT + mật khẩu, có reCAPTCHA) | AF14: Lần mở đầu bị Cloudflare 520, thử lại thì vào được; mã tra cứu = TransactionID; project đã có adapter misa | AG14: https://www.meinvoice.vn/tra-cuu/ | AJ14: =IFERROR(IF(INDEX('WBS2'!$I$2:$I$25,MATCH($C14,'WBS2'!$F$2:$F$25,0))="","",INDEX('WBS2'!$I$2:$I$25,MATCH($C14,'WBS2'!$F$2:$F$25,0))),"") | AK14: =IFERROR(IF(INDEX('WBS2'!$I$27:$I$162,MATCH($C14,'WBS2'!$F$27:$F$162,0))="","",INDEX('WBS2'!$I$27:$I$162,MATCH($C14,'WBS2'!$F$27:$F$162,0))),"") -> Hoàn thành | AL14: =IFERROR(IF(OR($AK14="Chưa hoàn thành",$AK14="Sẵn sàng"),INDEX('WBS2'!$H$27:$H$162,MATCH($C14,'WBS2'!$F$27:$F$162,0)),""),"") | AM14: =IFERROR(IF(INDEX('WBS2'!$J$27:$J$162,MATCH($C14,'WBS2'!$F$27:$F$162,0))="","",INDEX('WBS2'!$J$27:$J$162,MATCH($C14,'WBS2'!$F$27:$F$162,0))),"") | AN14: =IFERROR(IF(INDEX('WBS2'!$I$163:$I$298,MATCH($C14,'WBS2'!$F$163:$F$298,0))="","",INDEX('WBS2'!$I$163:$I$298,MATCH($C14,'WBS2'!$F$163:$F$298,0))),"") -> Hoàn thành | AO14: =IFERROR(IF(OR($AN14="Chưa hoàn thành",$AN14="Sẵn sàng"),INDEX('WBS2'!$H$163:$H$298,MATCH($C14,'WBS2'!$F$163:$F$298,0)),""),"") | AP14: =IFERROR(IF(INDEX('WBS2'!$J$163:$J$298,MATCH($C14,'WBS2'!$F$163:$F$298,0))="","",INDEX('WBS2'!$J$163:$J$298,MATCH($C14,'WBS2'!$F$163:$F$298,0))),"")
A15: 14 | B15: Công ty TNHH Hóa đơn điện tử M-INVOICE | C15: 0106026495 | D15: Số nhà 16, ngõ 269/1 đường Giáp Bát, phường Giáp Bát, quận Hoàng Mai, Tp Hà Nội | E15: https://minvoice.vn/ | F15: Không có captcha | G15: https://tracuuhoadon.minvoice.com.vn/tra-cuu-hoa-don | H15: =IF(N15<>"OK","",IF(IF(O15="✓","Mã tra cứu|","")&IF(P15="✓","MST người bán|","")&IF(Q15="✓","MST người mua|","")&IF(R15="✓","Mẫu số / Ký hiệu|","")&IF(S15="✓","Số HĐ|","")&IF(T15="✓","Ngày lập|","")&IF(U15="✓","Tổng tiền|","")&IF(V15="✓","Mã CQT|","")&IF(W15="✓","Upload XML|","")&IF(X15="✓","Captcha ảnh|","")&IF(Y15="✓","Captcha dạng tích|","")&IF(Z15="✓","Captcha khác (slider/hình)|","")&IF(AA15="✓","Đăng nhập|","")&IF(AB15="✓","Email/SĐT/OTP|","")="","(không có tham số)",SUBSTITUTE(LEFT(IF(O15="✓","Mã tra cứu|","")&IF(P15="✓","MST người bán|","")&IF(Q15="✓","MST người mua|","")&IF(R15="✓","Mẫu số / Ký hiệu|","")&IF(S15="✓","Số HĐ|","")&IF(T15="✓","Ngày lập|","")&IF(U15="✓","Tổng tiền|","")&IF(V15="✓","Mã CQT|","")&IF(W15="✓","Upload XML|","")&IF(X15="✓","Captcha ảnh|","")&IF(Y15="✓","Captcha dạng tích|","")&IF(Z15="✓","Captcha khác (slider/hình)|","")&IF(AA15="✓","Đăng nhập|","")&IF(AB15="✓","Email/SĐT/OTP|",""),LEN(IF(O15="✓","Mã tra cứu|","")&IF(P15="✓","MST người bán|","")&IF(Q15="✓","MST người mua|","")&IF(R15="✓","Mẫu số / Ký hiệu|","")&IF(S15="✓","Số HĐ|","")&IF(T15="✓","Ngày lập|","")&IF(U15="✓","Tổng tiền|","")&IF(V15="✓","Mã CQT|","")&IF(W15="✓","Upload XML|","")&IF(X15="✓","Captcha ảnh|","")&IF(Y15="✓","Captcha dạng tích|","")&IF(Z15="✓","Captcha khác (slider/hình)|","")&IF(AA15="✓","Đăng nhập|","")&IF(AB15="✓","Email/SĐT/OTP|",""))-1),"|"," + "))) -> Mã tra cứu + MST người bán | N15: OK | O15: ✓ | P15: ✓ | AC15: 2 | AD15: không có | AE15: Tab 'File': upload .zip ≤2MB; tab 'Tài khoản': đăng nhập; tab 'Đơn vị đặc thù': MST bán + mã khách hàng; tab Chứng từ, Biên lai | AF15: SPA React/Ant Design; ô MST nhận MST bên bán hoặc CCCD; mã tra cứu = số bảo mật; project đã có adapter minvoice | AG15: https://tracuuhoadon.minvoice.com.vn/tra-cuu-hoa-don | AJ15: =IFERROR(IF(INDEX('WBS2'!$I$2:$I$25,MATCH($C15,'WBS2'!$F$2:$F$25,0))="","",INDEX('WBS2'!$I$2:$I$25,MATCH($C15,'WBS2'!$F$2:$F$25,0))),"") | AK15: =IFERROR(IF(INDEX('WBS2'!$I$27:$I$162,MATCH($C15,'WBS2'!$F$27:$F$162,0))="","",INDEX('WBS2'!$I$27:$I$162,MATCH($C15,'WBS2'!$F$27:$F$162,0))),"") -> Hoàn thành | AL15: =IFERROR(IF(OR($AK15="Chưa hoàn thành",$AK15="Sẵn sàng"),INDEX('WBS2'!$H$27:$H$162,MATCH($C15,'WBS2'!$F$27:$F$162,0)),""),"") | AM15: =IFERROR(IF(INDEX('WBS2'!$J$27:$J$162,MATCH($C15,'WBS2'!$F$27:$F$162,0))="","",INDEX('WBS2'!$J$27:$J$162,MATCH($C15,'WBS2'!$F$27:$F$162,0))),"") | AN15: =IFERROR(IF(INDEX('WBS2'!$I$163:$I$298,MATCH($C15,'WBS2'!$F$163:$F$298,0))="","",INDEX('WBS2'!$I$163:$I$298,MATCH($C15,'WBS2'!$F$163:$F$298,0))),"") -> Hoàn thành | AO15: =IFERROR(IF(OR($AN15="Chưa hoàn thành",$AN15="Sẵn sàng"),INDEX('WBS2'!$H$163:$H$298,MATCH($C15,'WBS2'!$F$163:$F$298,0)),""),"") | AP15: =IFERROR(IF(INDEX('WBS2'!$J$163:$J$298,MATCH($C15,'WBS2'!$F$163:$F$298,0))="","",INDEX('WBS2'!$J$163:$J$298,MATCH($C15,'WBS2'!$F$163:$F$298,0))),"")
A16: 15 | B16: Công ty Cổ phần Phát triển công nghệ Nguyễn Minh | C16: 0313906508 | D16: Số 11/8 Tân Quý, phường Tân Quý, quận Tân Phú, Tp Hồ Chí Minh | E16: www.nguyenminhvat.vn | H16: =IF(N16<>"OK","",IF(IF(O16="✓","Mã tra cứu|","")&IF(P16="✓","MST người bán|","")&IF(Q16="✓","MST người mua|","")&IF(R16="✓","Mẫu số / Ký hiệu|","")&IF(S16="✓","Số HĐ|","")&IF(T16="✓","Ngày lập|","")&IF(U16="✓","Tổng tiền|","")&IF(V16="✓","Mã CQT|","")&IF(W16="✓","Upload XML|","")&IF(X16="✓","Captcha ảnh|","")&IF(Y16="✓","Captcha dạng tích|","")&IF(Z16="✓","Captcha khác (slider/hình)|","")&IF(AA16="✓","Đăng nhập|","")&IF(AB16="✓","Email/SĐT/OTP|","")="","(không có tham số)",SUBSTITUTE(LEFT(IF(O16="✓","Mã tra cứu|","")&IF(P16="✓","MST người bán|","")&IF(Q16="✓","MST người mua|","")&IF(R16="✓","Mẫu số / Ký hiệu|","")&IF(S16="✓","Số HĐ|","")&IF(T16="✓","Ngày lập|","")&IF(U16="✓","Tổng tiền|","")&IF(V16="✓","Mã CQT|","")&IF(W16="✓","Upload XML|","")&IF(X16="✓","Captcha ảnh|","")&IF(Y16="✓","Captcha dạng tích|","")&IF(Z16="✓","Captcha khác (slider/hình)|","")&IF(AA16="✓","Đăng nhập|","")&IF(AB16="✓","Email/SĐT/OTP|",""),LEN(IF(O16="✓","Mã tra cứu|","")&IF(P16="✓","MST người bán|","")&IF(Q16="✓","MST người mua|","")&IF(R16="✓","Mẫu số / Ký hiệu|","")&IF(S16="✓","Số HĐ|","")&IF(T16="✓","Ngày lập|","")&IF(U16="✓","Tổng tiền|","")&IF(V16="✓","Mã CQT|","")&IF(W16="✓","Upload XML|","")&IF(X16="✓","Captcha ảnh|","")&IF(Y16="✓","Captcha dạng tích|","")&IF(Z16="✓","Captcha khác (slider/hình)|","")&IF(AA16="✓","Đăng nhập|","")&IF(AB16="✓","Email/SĐT/OTP|",""))-1),"|"," + "))) | AJ16: =IFERROR(IF(INDEX('WBS2'!$I$2:$I$25,MATCH($C16,'WBS2'!$F$2:$F$25,0))="","",INDEX('WBS2'!$I$2:$I$25,MATCH($C16,'WBS2'!$F$2:$F$25,0))),"") | AK16: =IFERROR(IF(INDEX('WBS2'!$I$27:$I$162,MATCH($C16,'WBS2'!$F$27:$F$162,0))="","",INDEX('WBS2'!$I$27:$I$162,MATCH($C16,'WBS2'!$F$27:$F$162,0))),"") -> Chưa hoàn thành | AL16: =IFERROR(IF(OR($AK16="Chưa hoàn thành",$AK16="Sẵn sàng"),INDEX('WBS2'!$H$27:$H$162,MATCH($C16,'WBS2'!$F$27:$F$162,0)),""),"") -> 46446 | AM16: =IFERROR(IF(INDEX('WBS2'!$J$27:$J$162,MATCH($C16,'WBS2'!$F$27:$F$162,0))="","",INDEX('WBS2'!$J$27:$J$162,MATCH($C16,'WBS2'!$F$27:$F$162,0))),"") -> Chưa làm – danh sách chưa có link tra cứu, chưa có HĐ thật | AN16: =IFERROR(IF(INDEX('WBS2'!$I$163:$I$298,MATCH($C16,'WBS2'!$F$163:$F$298,0))="","",INDEX('WBS2'!$I$163:$I$298,MATCH($C16,'WBS2'!$F$163:$F$298,0))),"") -> Chưa hoàn thành | AO16: =IFERROR(IF(OR($AN16="Chưa hoàn thành",$AN16="Sẵn sàng"),INDEX('WBS2'!$H$163:$H$298,MATCH($C16,'WBS2'!$F$163:$F$298,0)),""),"") -> 46446 | AP16: =IFERROR(IF(INDEX('WBS2'!$J$163:$J$298,MATCH($C16,'WBS2'!$F$163:$F$298,0))="","",INDEX('WBS2'!$J$163:$J$298,MATCH($C16,'WBS2'!$F$163:$F$298,0))),"") -> Chưa có mail/PDF nào của NCC này (kiểm DB 27/10)
A17: 16 | B17: Công ty TNHH Phát triển công nghệ Thái Sơn | C17: 0101300842 | D17: Số 362, Phố Huế, phường Phố Huế quận Hai Bà Trưng, Tp Hà Nội | E17: https://www.einvoice.vn | F17: có captcha | G17: https://tracuutvan.einvoice.com.vn/ | H17: =IF(N17<>"OK","",IF(IF(O17="✓","Mã tra cứu|","")&IF(P17="✓","MST người bán|","")&IF(Q17="✓","MST người mua|","")&IF(R17="✓","Mẫu số / Ký hiệu|","")&IF(S17="✓","Số HĐ|","")&IF(T17="✓","Ngày lập|","")&IF(U17="✓","Tổng tiền|","")&IF(V17="✓","Mã CQT|","")&IF(W17="✓","Upload XML|","")&IF(X17="✓","Captcha ảnh|","")&IF(Y17="✓","Captcha dạng tích|","")&IF(Z17="✓","Captcha khác (slider/hình)|","")&IF(AA17="✓","Đăng nhập|","")&IF(AB17="✓","Email/SĐT/OTP|","")="","(không có tham số)",SUBSTITUTE(LEFT(IF(O17="✓","Mã tra cứu|","")&IF(P17="✓","MST người bán|","")&IF(Q17="✓","MST người mua|","")&IF(R17="✓","Mẫu số / Ký hiệu|","")&IF(S17="✓","Số HĐ|","")&IF(T17="✓","Ngày lập|","")&IF(U17="✓","Tổng tiền|","")&IF(V17="✓","Mã CQT|","")&IF(W17="✓","Upload XML|","")&IF(X17="✓","Captcha ảnh|","")&IF(Y17="✓","Captcha dạng tích|","")&IF(Z17="✓","Captcha khác (slider/hình)|","")&IF(AA17="✓","Đăng nhập|","")&IF(AB17="✓","Email/SĐT/OTP|",""),LEN(IF(O17="✓","Mã tra cứu|","")&IF(P17="✓","MST người bán|","")&IF(Q17="✓","MST người mua|","")&IF(R17="✓","Mẫu số / Ký hiệu|","")&IF(S17="✓","Số HĐ|","")&IF(T17="✓","Ngày lập|","")&IF(U17="✓","Tổng tiền|","")&IF(V17="✓","Mã CQT|","")&IF(W17="✓","Upload XML|","")&IF(X17="✓","Captcha ảnh|","")&IF(Y17="✓","Captcha dạng tích|","")&IF(Z17="✓","Captcha khác (slider/hình)|","")&IF(AA17="✓","Đăng nhập|","")&IF(AB17="✓","Email/SĐT/OTP|",""))-1),"|"," + "))) -> Mã tra cứu + MST người bán + Captcha ảnh | I17: Xong | K17: 0.8924 | L17: g_200x70 | N17: OK | O17: ✓ | P17: ✓ | X17: ✓ | AC17: 3 | AD17: ảnh 200x70 (/DefaultCaptcha/Generate, hiển thị 172x35) | AF17: Mã tra cứu ghi là 'Mã nhận hóa đơn' | AG17: https://tracuutvan.einvoice.com.vn/ | AJ17: =IFERROR(IF(INDEX('WBS2'!$I$2:$I$25,MATCH($C17,'WBS2'!$F$2:$F$25,0))="","",INDEX('WBS2'!$I$2:$I$25,MATCH($C17,'WBS2'!$F$2:$F$25,0))),"") -> Hoàn thành | AK17: =IFERROR(IF(INDEX('WBS2'!$I$27:$I$162,MATCH($C17,'WBS2'!$F$27:$F$162,0))="","",INDEX('WBS2'!$I$27:$I$162,MATCH($C17,'WBS2'!$F$27:$F$162,0))),"") -> Hoàn thành | AL17: =IFERROR(IF(OR($AK17="Chưa hoàn thành",$AK17="Sẵn sàng"),INDEX('WBS2'!$H$27:$H$162,MATCH($C17,'WBS2'!$F$27:$F$162,0)),""),"") | AM17: =IFERROR(IF(INDEX('WBS2'!$J$27:$J$162,MATCH($C17,'WBS2'!$F$27:$F$162,0))="","",INDEX('WBS2'!$J$27:$J$162,MATCH($C17,'WBS2'!$F$27:$F$162,0))),"") -> lấy được đa số, Grab không lấy được | AN17: =IFERROR(IF(INDEX('WBS2'!$I$163:$I$298,MATCH($C17,'WBS2'!$F$163:$F$298,0))="","",INDEX('WBS2'!$I$163:$I$298,MATCH($C17,'WBS2'!$F$163:$F$298,0))),"") -> Hoàn thành | AO17: =IFERROR(IF(OR($AN17="Chưa hoàn thành",$AN17="Sẵn sàng"),INDEX('WBS2'!$H$163:$H$298,MATCH($C17,'WBS2'!$F$163:$F$298,0)),""),"") | AP17: =IFERROR(IF(INDEX('WBS2'!$J$163:$J$298,MATCH($C17,'WBS2'!$F$163:$F$298,0))="","",INDEX('WBS2'!$J$163:$J$298,MATCH($C17,'WBS2'!$F$163:$F$298,0))),"")
A18: 17 | B18: Công ty TNHH Máy tính và truyền thông công nghệ kết nối | C18: 0306784030 | D18: 213/59/17 Quang Trung, phường 10, quận Gò Vấp, Tp Hồ Chí Minh | E18: https://ehoadon.online | F18: captcha dạng tích | G18: https://ehoadon.online/einvoice/lookup | H18: =IF(N18<>"OK","",IF(IF(O18="✓","Mã tra cứu|","")&IF(P18="✓","MST người bán|","")&IF(Q18="✓","MST người mua|","")&IF(R18="✓","Mẫu số / Ký hiệu|","")&IF(S18="✓","Số HĐ|","")&IF(T18="✓","Ngày lập|","")&IF(U18="✓","Tổng tiền|","")&IF(V18="✓","Mã CQT|","")&IF(W18="✓","Upload XML|","")&IF(X18="✓","Captcha ảnh|","")&IF(Y18="✓","Captcha dạng tích|","")&IF(Z18="✓","Captcha khác (slider/hình)|","")&IF(AA18="✓","Đăng nhập|","")&IF(AB18="✓","Email/SĐT/OTP|","")="","(không có tham số)",SUBSTITUTE(LEFT(IF(O18="✓","Mã tra cứu|","")&IF(P18="✓","MST người bán|","")&IF(Q18="✓","MST người mua|","")&IF(R18="✓","Mẫu số / Ký hiệu|","")&IF(S18="✓","Số HĐ|","")&IF(T18="✓","Ngày lập|","")&IF(U18="✓","Tổng tiền|","")&IF(V18="✓","Mã CQT|","")&IF(W18="✓","Upload XML|","")&IF(X18="✓","Captcha ảnh|","")&IF(Y18="✓","Captcha dạng tích|","")&IF(Z18="✓","Captcha khác (slider/hình)|","")&IF(AA18="✓","Đăng nhập|","")&IF(AB18="✓","Email/SĐT/OTP|",""),LEN(IF(O18="✓","Mã tra cứu|","")&IF(P18="✓","MST người bán|","")&IF(Q18="✓","MST người mua|","")&IF(R18="✓","Mẫu số / Ký hiệu|","")&IF(S18="✓","Số HĐ|","")&IF(T18="✓","Ngày lập|","")&IF(U18="✓","Tổng tiền|","")&IF(V18="✓","Mã CQT|","")&IF(W18="✓","Upload XML|","")&IF(X18="✓","Captcha ảnh|","")&IF(Y18="✓","Captcha dạng tích|","")&IF(Z18="✓","Captcha khác (slider/hình)|","")&IF(AA18="✓","Đăng nhập|","")&IF(AB18="✓","Email/SĐT/OTP|",""))-1),"|"," + "))) -> Mã tra cứu + MST người bán + Captcha dạng tích | N18: OK | O18: ✓ | P18: ✓ | Y18: ✓ | AC18: 3 | AD18: reCAPTCHA v2 checkbox (Enterprise) | AE18: Tab 'Tập tin XML': upload XML (cũng có reCAPTCHA) | AF18: MST đơn vị phát hành (bên bán) + mã tra cứu | AG18: https://ehoadon.online/einvoice/lookup | AJ18: =IFERROR(IF(INDEX('WBS2'!$I$2:$I$25,MATCH($C18,'WBS2'!$F$2:$F$25,0))="","",INDEX('WBS2'!$I$2:$I$25,MATCH($C18,'WBS2'!$F$2:$F$25,0))),"") | AK18: =IFERROR(IF(INDEX('WBS2'!$I$27:$I$162,MATCH($C18,'WBS2'!$F$27:$F$162,0))="","",INDEX('WBS2'!$I$27:$I$162,MATCH($C18,'WBS2'!$F$27:$F$162,0))),"") -> Chưa hoàn thành | AL18: =IFERROR(IF(OR($AK18="Chưa hoàn thành",$AK18="Sẵn sàng"),INDEX('WBS2'!$H$27:$H$162,MATCH($C18,'WBS2'!$F$27:$F$162,0)),""),"") -> 46446 | AM18: =IFERROR(IF(INDEX('WBS2'!$J$27:$J$162,MATCH($C18,'WBS2'!$F$27:$F$162,0))="","",INDEX('WBS2'!$J$27:$J$162,MATCH($C18,'WBS2'!$F$27:$F$162,0))),"") -> Không làm được qua link tra cứu – bị chặn bởi reCAPTCHA v2 (server kiểm), lấy qua mail. dính reCAPTCHA Enterprise | AN18: =IFERROR(IF(INDEX('WBS2'!$I$163:$I$298,MATCH($C18,'WBS2'!$F$163:$F$298,0))="","",INDEX('WBS2'!$I$163:$I$298,MATCH($C18,'WBS2'!$F$163:$F$298,0))),"") -> Chưa hoàn thành | AO18: =IFERROR(IF(OR($AN18="Chưa hoàn thành",$AN18="Sẵn sàng"),INDEX('WBS2'!$H$163:$H$298,MATCH($C18,'WBS2'!$F$163:$F$298,0)),""),"") -> 46446 | AP18: =IFERROR(IF(INDEX('WBS2'!$J$163:$J$298,MATCH($C18,'WBS2'!$F$163:$F$298,0))="","",INDEX('WBS2'!$J$163:$J$298,MATCH($C18,'WBS2'!$F$163:$F$298,0))),"") -> Chưa có mail/PDF nào của NCC này (kiểm DB 27/10)
